<mujoco model="ur5e">
  <compiler angle="radian" meshdir="asset" autolimits="true"/>

  <option integrator="implicitfast"/>

  <default>
    <default class="ur5e">
      <material specular="0.5" shininess="0.25"/>
      <joint axis="0 1 0" range="-6.28319 6.28319" armature="0.1"/>
      <general gaintype="fixed" biastype="affine" ctrlrange="-6.2831 6.2831" gainprm="2000" biasprm="0 -2000 -400"
        forcerange="-150 150"/>
      <default class="size3">
        <default class="size3_limited">
          <joint range="-3.1415 3.1415"/>
          <general ctrlrange="-3.1415 3.1415"/>
        </default>
      </default>
      <default class="size1">
        <general gainprm="500" biasprm="0 -500 -100" forcerange="-28 28"/>
      </default>
      <default class="visual">
        <geom type="mesh" contype="0" conaffinity="0" group="2"/>
      </default>
      <default class="collision">
        <geom type="capsule" group="3"/>
        <default class="eef_collision">
          <geom type="cylinder"/>
        </default>
      </default>
      <site size="0.001" rgba="0.5 0.5 0.5 0.3" group="4"/>
    </default>

    <default class="2f85">
      <mesh scale="0.001 0.001 0.001"/>
      <general biastype="affine"/>
      <joint axis="1 0 0" limited="false"/>

      <default class="robotiq_85_outter_knuckle_link">
        <joint limited="true" range="0 0.834" solimplimit="0.95 0.99 0.001" solreflimit="0.005 1"
               armature="0.005" damping="0.1"/>
      </default>
      <default class="robotiq_85_finger_tip_link">
        <joint limited="true" armature="0.001" range="-0.872664 0.872664" pos="0 -0.018 0.0065"
               solimplimit="0.95 0.99 0.001" solreflimit="0.005 1"/>
      </default>
      <default class="robotiq_85_inner_knuckle_link">
        <joint limited="true" armature="0.001" range="-0.29670597283 0.8"
               stiffness="0.05" springref="2.62" damping="0.00125"/>
      </default>
      <default class="robotiq_85_finger_link">
        <joint limited="true" armature="0.001" range="-1.57 0"
               solimplimit="0.95 0.99 0.001" solreflimit="0.005 1"/>
      </default>

      <default class="visual_2f85">
        <geom type="mesh" contype="0" conaffinity="0" group="2"/>
      </default>
      <default class="collision_2f85">
        <geom type="mesh" group="3"/>
        <default class="robotiq_85_finger_pad_box1">
          <geom mass="0" type="box" pos="0 -0.0026 0.028125" size="0.011 0.004 0.009375"
                friction="0.7" solimp="0.95 0.99 0.001" solref="0.004 1"
                priority="1" rgba="0.55 0.55 0.55 1"/>
        </default>
        <default class="robotiq_85_finger_pad_box2">
          <geom mass="0" type="box" pos="0 -0.0026 0.009375" size="0.011 0.004 0.009375"
                friction="0.6" solimp="0.95 0.99 0.001" solref="0.004 1"
                priority="1" rgba="0.45 0.45 0.45 1"/>
        </default>
      </default>
    </default>
  </default>

  <asset>
    <material class="ur5e" name="black" rgba="0.033 0.033 0.033 1"/>
    <material class="ur5e" name="jointgray" rgba="0.278 0.278 0.278 1"/>
    <material class="ur5e" name="linkgray" rgba="0.82 0.82 0.82 1"/>
    <material class="ur5e" name="urblue" rgba="0.49 0.678 0.8 1"/>
    <material class="ur5e" name="grippergray" rgba="0.65 0.65 0.68 1"/>

    <material name="metal" rgba="0.58 0.58 0.58 1"/>
    <material name="silicone" rgba="0.1882 0.1882 0.1882 1"/>
    <material name="gray" rgba="0.4627 0.4627 0.4627 1"/>
    <material name="black_2f85" rgba="0.149 0.149 0.149 1"/>

    <mesh file="base_0.obj"/>
    <mesh file="base_1.obj"/>
    <mesh file="shoulder_0.obj"/>
    <mesh file="shoulder_1.obj"/>
    <mesh file="shoulder_2.obj"/>
    <mesh file="upperarm_0.obj"/>
    <mesh file="upperarm_1.obj"/>
    <mesh file="upperarm_2.obj"/>
    <mesh file="upperarm_3.obj"/>
    <mesh file="forearm_0.obj"/>
    <mesh file="forearm_1.obj"/>
    <mesh file="forearm_2.obj"/>
    <mesh file="forearm_3.obj"/>
    <mesh file="wrist1_0.obj"/>
    <mesh file="wrist1_1.obj"/>
    <mesh file="wrist1_2.obj"/>
    <mesh file="wrist2_0.obj"/>
    <mesh file="wrist2_1.obj"/>
    <mesh file="wrist2_2.obj"/>
    <mesh file="wrist3.obj"/>
    <mesh name="apriltag_plane" file="apriltag_plane.obj" scale="0.5 0.5 0.5"/>

    <!-- 用你现在 asset 目录里那套“别人版本”的文件名 -->
    <mesh class="2f85" name="base_mount" file="base_mount.stl"/>
    <mesh class="2f85" name="robotiq_85_base_link" file="robotiq_85_base_link.stl"/>
    <mesh class="2f85" name="robotiq_85_outter_knuckle_link" file="robotiq_85_outter_knuckle_link.stl"/>
    <mesh class="2f85" name="robotiq_85_finger_link" file="robotiq_85_finger_link.stl"/>
    <mesh class="2f85" name="robotiq_85_finger_tip_link" file="robotiq_85_finger_tip_link.stl"/>
    <mesh class="2f85" name="robotiq_85_finger_pad" file="robotiq_85_finger_pad.stl"/>
    <mesh class="2f85" name="robotiq_85_finger_silicone_pad" file="robotiq_85_finger_silicone_pad.stl"/>
    <mesh class="2f85" name="robotiq_85_inner_knuckle_link" file="robotiq_85_inner_knuckle_link.stl"/>

    <texture
      name="apriltag_tex"
      type="2d"
      file="assets/tag36h11_0.png"
      width="100"
      height="100"
    />
    <material name="mat_white" rgba="1 1 1 1"/>
    <material name="apriltag_mat" texture="apriltag_tex" texuniform="true"/>
  </asset>

  <worldbody>
    <light name="spotlight" mode="targetbodycom" target="wrist_2_link" pos="0 -1 2"/>

    <body name="base" quat="0 0 0 -1" childclass="ur5e">
      <inertial mass="4.0" pos="0 0 0" diaginertia="0.00443333156 0.00443333156 0.0072"/>
      <geom mesh="base_0" material="black" class="visual"/>
      <geom mesh="base_1" material="jointgray" class="visual"/>

      <body name="shoulder_link" pos="0 0 0.163">
        <inertial mass="3.7" pos="0 0 0" diaginertia="0.0102675 0.0102675 0.00666"/>
        <joint name="shoulder_pan_joint" class="size3" axis="0 0 1"/>
        <geom mesh="shoulder_0" material="urblue" class="visual"/>
        <geom mesh="shoulder_1" material="black" class="visual"/>
        <geom mesh="shoulder_2" material="jointgray" class="visual"/>
        <geom class="collision" size="0.06 0.06" pos="0 0 -0.04"/>

        <body name="upper_arm_link" pos="0 0.138 0" quat="1 0 1 0">
          <inertial mass="8.393" pos="0 0 0.2125" diaginertia="0.133886 0.133886 0.0151074"/>
          <joint name="shoulder_lift_joint" class="size3"/>
          <geom mesh="upperarm_0" material="linkgray" class="visual"/>
          <geom mesh="upperarm_1" material="black" class="visual"/>
          <geom mesh="upperarm_2" material="jointgray" class="visual"/>
          <geom mesh="upperarm_3" material="urblue" class="visual"/>
          <geom class="collision" pos="0 -0.04 0" quat="1 1 0 0" size="0.06 0.06"/>
          <geom class="collision" size="0.05 0.2" pos="0 0 0.2"/>

          <body name="forearm_link" pos="0 -0.131 0.425">
            <inertial mass="2.275" pos="0 0 0.196" diaginertia="0.0311796 0.0311796 0.004095"/>
            <joint name="elbow_joint" class="size3_limited"/>
            <geom mesh="forearm_0" material="urblue" class="visual"/>
            <geom mesh="forearm_1" material="linkgray" class="visual"/>
            <geom mesh="forearm_2" material="black" class="visual"/>
            <geom mesh="forearm_3" material="jointgray" class="visual"/>
            <geom class="collision" pos="0 0.08 0" quat="1 1 0 0" size="0.055 0.06"/>
            <geom class="collision" size="0.038 0.19" pos="0 0 0.2"/>

            <body name="wrist_1_link" pos="0 0 0.392" quat="1 0 1 0">
              <inertial mass="1.219" pos="0 0.127 0" diaginertia="0.0025599 0.0025599 0.0021942"/>
              <joint name="wrist_1_joint" class="size1"/>
              <geom mesh="wrist1_0" material="black" class="visual"/>
              <geom mesh="wrist1_1" material="urblue" class="visual"/>
              <geom mesh="wrist1_2" material="jointgray" class="visual"/>
              <geom class="collision" pos="0 0.05 0" quat="1 1 0 0" size="0.04 0.07"/>

              <body name="wrist_2_link" pos="0 0.127 0">
                <inertial mass="1.219" pos="0 0 0.1" diaginertia="0.0025599 0.0025599 0.0021942"/>
                <joint name="wrist_2_joint" axis="0 0 1" class="size1"/>
                <geom mesh="wrist2_0" material="black" class="visual"/>
                <geom mesh="wrist2_1" material="urblue" class="visual"/>
                <geom mesh="wrist2_2" material="jointgray" class="visual"/>
                <geom class="collision" size="0.04 0.06" pos="0 0 0.04"/>
                <geom class="collision" pos="0 0.02 0.1" quat="1 1 0 0" size="0.04 0.04"/>

                <body name="wrist_3_link" pos="0 0 0.1">
                  <inertial mass="0.1889" pos="0 0.0771683 0" quat="1 0 0 1"
                    diaginertia="0.000132134 9.90863e-05 9.90863e-05"/>
                  <joint name="wrist_3_joint" class="size1"/>
                  <geom material="linkgray" mesh="wrist3" class="visual"/>
                  <geom class="eef_collision" pos="0 0.08 0" quat="1 1 0 0" size="0.04 0.02"/>
                  <site name="attachment_site" pos="0 0.2 0" quat="0.707106781186548 0.707106781186548 0 0"/>

                  <camera
                    name="end_effector_camera"
                    pos="0.0 0.20 0.0"
                    quat="0.707106781186548 0.707106781186548 0 0"
                    fovy="90"
                  />

                  <!-- 按别人方案改夹爪安装，只动夹爪 -->
                  <body name="tool0" pos="0 0.090 0" quat="0.707107 -0.707107 0 0">
                    <inertial pos="0 0.090 0" quat="0.707107 -0.707107 0 0" mass="0" diaginertia="0 0 0"/>
                    <site name="wrist_3_site" type="cylinder" size="0.0375 0.0001" pos="0 0 0" rgba="1 0 0 1"/>

                    <body name="base_mount" pos="0 0 0.007" quat="1 0 0 1" childclass="2f85">
                      <geom class="visual_2f85" mesh="base_mount" material="black_2f85"/>
                      <geom class="collision_2f85" mesh="base_mount"/>

                      <body name="robotiq_85_base_link" pos="0 0 0.0038" quat="1 0 0 -1">
                        <inertial mass="0.777441" pos="0 -2.70394e-05 0.0354675" quat="1 -0.00152849 0 0"
                          diaginertia="0.000260285 0.000225381 0.000152708"/>
                        <geom class="visual_2f85" mesh="robotiq_85_base_link" material="black_2f85"/>
                        <geom class="collision_2f85" mesh="robotiq_85_base_link"/>

                        <body name="robotiq_85_right_knuckle_link" pos="0 0.0306011 0.054904">
                          <inertial mass="0.00899563" pos="2.96931e-12 0.0177547 0.00107314"
                            quat="0.681301 0.732003 0 0"
                            diaginertia="1.72352e-06 1.60906e-06 3.22006e-07"/>
                          <joint name="robotiq_85_right_knuckle_joint" class="robotiq_85_outter_knuckle_link"/>
                          <geom class="visual_2f85" mesh="robotiq_85_outter_knuckle_link" material="gray"/>
                          <geom class="collision_2f85" mesh="robotiq_85_outter_knuckle_link"/>

                          <body name="robotiq_85_right_finger_link" pos="0 0.0315 -0.0041">
                            <inertial mass="0.0140974" pos="0 0.00301209 0.0232175"
                              quat="0.705636 -0.0455904 0.0455904 0.705636"
                              diaginertia="4.16206e-06 3.52216e-06 8.88131e-07"/>
                            <joint name="robotiq_85_right_finger_joint" class="robotiq_85_finger_link"/>
                            <geom class="visual_2f85" mesh="robotiq_85_finger_link" material="black_2f85"/>
                            <geom class="collision_2f85" mesh="robotiq_85_finger_link"/>
                          </body>
                        </body>

                        <body name="robotiq_85_right_inner_knuckle_link" pos="0 0.0132 0.0609">
                          <inertial mass="0.0221642" pos="-8.65005e-09 0.0181624 0.0212658"
                            quat="0.663403 -0.244737 0.244737 0.663403"
                            diaginertia="8.96853e-06 6.71733e-06 2.63931e-06"/>
                          <joint name="robotiq_85_right_inner_knuckle_joint" class="robotiq_85_inner_knuckle_link"/>
                          <geom class="visual_2f85" mesh="robotiq_85_inner_knuckle_link" material="black_2f85"/>
                          <geom class="collision_2f85" mesh="robotiq_85_inner_knuckle_link"/>

                          <body name="robotiq_85_right_finger_tip_link" pos="0 0.055 0.0375">
                            <inertial mass="0.0125222" pos="0 -0.011046 0.0124786" quat="1 0.1664 0 0"
                              diaginertia="2.67415e-06 2.4559e-06 6.02031e-07"/>
                            <joint name="robotiq_85_right_finger_tip_joint" class="robotiq_85_finger_tip_link"/>
                            <geom class="visual_2f85" mesh="robotiq_85_finger_tip_link" material="black_2f85"/>
                            <geom class="collision_2f85" mesh="robotiq_85_finger_tip_link"/>

                            <body name="right_pad" pos="0 -0.0189 0.01352">
                              <geom class="robotiq_85_finger_pad_box1"/>
                              <geom class="robotiq_85_finger_pad_box2"/>
                              <inertial mass="0.0035" pos="0 -0.0025 0.0185" quat="0.707107 0 0 0.707107"
                                diaginertia="4.73958e-07 3.64583e-07 1.23958e-07"/>
                              <geom class="visual_2f85" mesh="robotiq_85_finger_pad"/>
                              <site name="robotiq_85_finger_right_site" type="box" size="0.011 0.001 0.018125"
                                    pos="0 -0.01 0.01770" rgba="0.3 0.2 0.1 1.0"/>
                              <body name="right_silicone_pad">
                                <geom class="visual_2f85" mesh="robotiq_85_finger_silicone_pad" material="black_2f85"/>
                              </body>
                            </body>
                          </body>
                        </body>

                        <body name="robotiq_85_left_knuckle_link" pos="0 -0.0306011 0.054904" quat="0 0 0 1">
                          <inertial mass="0.00899563" pos="0 0.0177547 0.00107314" quat="0.681301 0.732003 0 0"
                            diaginertia="1.72352e-06 1.60906e-06 3.22006e-07"/>
                          <joint name="robotiq_85_left_knuckle_joint" class="robotiq_85_outter_knuckle_link"/>
                          <geom class="visual_2f85" mesh="robotiq_85_outter_knuckle_link" material="gray"/>
                          <geom class="collision_2f85" mesh="robotiq_85_outter_knuckle_link"/>

                          <body name="robotiq_85_left_finger_link" pos="0 0.0315 -0.0041">
                            <inertial mass="0.0140974" pos="0 0.00301209 0.0232175"
                              quat="0.705636 -0.0455904 0.0455904 0.705636"
                              diaginertia="4.16206e-06 3.52216e-06 8.88131e-07"/>
                            <joint name="robotiq_85_left_finger_joint" class="robotiq_85_finger_link"/>
                            <geom class="visual_2f85" mesh="robotiq_85_finger_link" material="black_2f85"/>
                            <geom class="collision_2f85" mesh="robotiq_85_finger_link"/>
                          </body>
                        </body>

                        <body name="robotiq_85_left_inner_knuckle_link" pos="0 -0.0132 0.0609" quat="0 0 0 1">
                          <inertial mass="0.0221642" pos="-8.65005e-09 0.0181624 0.0212658"
                            quat="0.663403 -0.244737 0.244737 0.663403"
                            diaginertia="8.96853e-06 6.71733e-06 2.63931e-06"/>
                          <joint name="robotiq_85_left_inner_knuckle_joint" class="robotiq_85_inner_knuckle_link"/>
                          <geom class="visual_2f85" mesh="robotiq_85_inner_knuckle_link" material="black_2f85"/>
                          <geom class="collision_2f85" mesh="robotiq_85_inner_knuckle_link"/>

                          <body name="robotiq_85_left_finger_tip_link" pos="0 0.055 0.0375">
                            <inertial mass="0.0125222" pos="0 -0.011046 0.0124786" quat="1 0.1664 0 0"
                              diaginertia="2.67415e-06 2.4559e-06 6.02031e-07"/>
                            <joint name="robotiq_85_left_finger_tip_joint" class="robotiq_85_finger_tip_link"/>
                            <geom class="visual_2f85" mesh="robotiq_85_finger_tip_link" material="black_2f85"/>
                            <geom class="collision_2f85" mesh="robotiq_85_finger_tip_link"/>

                            <body name="left_pad" pos="0 -0.0189 0.01352">
                              <geom class="robotiq_85_finger_pad_box1"/>
                              <geom class="robotiq_85_finger_pad_box2"/>
                              <inertial mass="0.0035" pos="0 -0.0025 0.0185" quat="1 0 0 1"
                                diaginertia="4.73958e-07 3.64583e-07 1.23958e-07"/>
                              <geom class="visual_2f85" mesh="robotiq_85_finger_pad"/>
                              <site name="robotiq_85_finger_left_site" type="box" size="0.011 0.001 0.018125"
                                    pos="0 -0.01 0.01770" rgba="0.3 0.2 0.1 1.0"/>
                              <body name="left_silicone_pad">
                                <geom class="visual_2f85" mesh="robotiq_85_finger_silicone_pad" material="black_2f85"/>
                              </body>
                            </body>
                          </body>
                        </body>

                      </body>
                    </body>

                  </body>
                </body>
              </body>
            </body>
          </body>
        </body>
      </body>
    </body>

    <body name="target" pos="-0.18 0.45 0.046" quat="1 0 0 0">
      <freejoint name="target_freejoint"/>
      <geom
        name="target_collision"
        type="box"
        size="0.03 0.03 0.03"
        mass="0.08"
        friction="2.5 0.05 0.01"
        rgba="0.85 0.85 0.85 1"
      />
      <geom
        name="target_tag_visual"
        type="mesh"
        mesh="apriltag_plane"
        pos="0 0 0.0305"
        material="apriltag_mat"
        contype="0"
        conaffinity="0"
      />
    </body>
  </worldbody>

  <contact>
    <exclude body1="robotiq_85_base_link" body2="robotiq_85_left_knuckle_link"/>
    <exclude body1="robotiq_85_base_link" body2="robotiq_85_right_knuckle_link"/>
    <exclude body1="robotiq_85_base_link" body2="robotiq_85_left_inner_knuckle_link"/>
    <exclude body1="robotiq_85_base_link" body2="robotiq_85_right_inner_knuckle_link"/>
    <exclude body1="robotiq_85_right_finger_link" body2="robotiq_85_right_finger_tip_link"/>
    <exclude body1="robotiq_85_left_finger_link" body2="robotiq_85_left_finger_tip_link"/>
  </contact>

  <tendon>
    <fixed name="split">
      <joint joint="robotiq_85_right_knuckle_joint" coef="0.5"/>
      <joint joint="robotiq_85_left_knuckle_joint" coef="0.5"/>
    </fixed>
  </tendon>

  <equality>
    <connect anchor="0 0 0" body1="robotiq_85_right_finger_tip_link" body2="robotiq_85_right_finger_link" solimp="0.95 0.99 0.001" solref="0.005 1"/>
    <connect anchor="0 0 0" body1="robotiq_85_left_finger_tip_link" body2="robotiq_85_left_finger_link" solimp="0.95 0.99 0.001" solref="0.005 1"/>
    <joint joint1="robotiq_85_right_knuckle_joint" joint2="robotiq_85_left_knuckle_joint" polycoef="0 1 0 0 0" solimp="0.95 0.99 0.001" solref="0.005 1"/>
  </equality>

  <sensor>
    <force name="force" site="wrist_3_site"/>
    <torque name="torque" site="wrist_3_site"/>
    <force name="right_finger" site="robotiq_85_finger_right_site"/>
    <force name="left_finger" site="robotiq_85_finger_left_site"/>
  </sensor>

  <actuator>
    <intvelocity name="shoulder_pan_vel_init" joint="shoulder_pan_joint" kp="800000" kv="1000" actrange="-500.9671 500.9671"/>
    <intvelocity name="shoulder_lift_vel_init" joint="shoulder_lift_joint" kp="800000" kv="1000" actrange="-500.9671 500.9671"/>
    <intvelocity name="elbow_vel_init" joint="elbow_joint" kp="800000" kv="1000" actrange="-500.9671 500.9671"/>
    <intvelocity name="wrist_1_vel_init" joint="wrist_1_joint" kp="100000" kv="100" actrange="-50.9671 50.9671"/>
    <intvelocity name="wrist_2_vel_init" joint="wrist_2_joint" kp="100000" kv="100" actrange="-50.9671 50.9671"/>
    <intvelocity name="wrist_3_vel_init" joint="wrist_3_joint" kp="100000" kv="100" actrange="-50.9671 50.9671"/>

    <general class="2f85" name="2f85_ctrl" tendon="split" forcerange="-10 10"/>
  </actuator>

  <keyframe>
    <key name="home" qpos="-1.5708 -1.5708 1.5708 -1.5708 -1.5708 0 0 0 0 0 0 0 0 0 -0.18 0.45 0.046 1 0 0 0"/>
  </keyframe>
</mujoco>
